<?xml version="1.0" encoding="utf-8"?>
<!-- This URDF was automatically created by SolidWorks to URDF Exporter! Originally created by Stephen Brawner (brawner@gmail.com) 
     Commit Version: 1.5.1-0-g916b5db  Build Version: 1.5.7152.31018
     For more information, please see http://wiki.ros.org/sw_urdf_exporter -->
<robot
  name="fr5_robot">

  <link name="world"/>
  <joint name="world" type="fixed">
    <parent link="world"/>
    <child link="base_link"/>
  </joint>

  <link
    name="base_link">
    <inertial>
      <origin
        xyz="-0.00044457 0.0004811 0.032592"
        rpy="0 0 0" />
      <mass
        value="1.62" />
      <inertia
        ixx="0.0024567"
        ixy="-1.5435E-05"
        ixz="-1.3507E-05"
        iyy="0.0024575"
        iyz="1.4421E-05"
        izz="0.0038879" />
    </inertial>
    <visual>
      <origin
        xyz="0 0 0"
        rpy="0 0 0" />
      <geometry>
        <mesh
          filename="package://frcobot_description/meshes/fr5/visual/base.dae" />
      </geometry>
      <material
        name="">
        <color
          rgba="0.89804 0.91765 0.92941 1" />
      </material>
    </visual>
    <collision>
      <origin
        xyz="0 0 0"
        rpy="0 0 0" />
      <geometry>
        <mesh
          filename="package://frcobot_description/meshes/fr5/collision/base_link.STL" />
      </geometry>
    </collision>
  </link>
  <link
    name="shoulder_Link">
    <inertial>
      <origin
        xyz="1.3785E-06 -0.0031495 0.14526"
        rpy="0 0 0" />
      <mass
        value="4.38" />
      <inertia
        ixx="0.010397"
        ixy="-1.005E-08"
        ixz="1.6274E-07"
        iyy="0.010278"
        iyz="0.00015856"
        izz="0.0076307" />
    </inertial>
    <visual>
      <origin
        xyz="0 0 0"
        rpy="0 0 0" />
      <geometry>
        <mesh
          filename="package://frcobot_description/meshes/fr5/visual/shoulder.dae" />
      </geometry>
      <material
        name="">
        <color
          rgba="0.89804 0.91765 0.92941 1" />
      </material>
    </visual>
    <collision>
      <origin
        xyz="0 0 0"
        rpy="0 0 0" />
      <geometry>
        <mesh
          filename="package://frcobot_description/meshes/fr5/collision/shoulder_Link.STL" />
      </geometry>
    </collision>
  </link>
  <joint
    name="j1"
    type="revolute">
    <origin
      xyz="0 0 0"
      rpy="0 0 0" />
    <parent
      link="base_link" />
    <child
      link="shoulder_Link" />
    <axis
      xyz="0 0 1" />
    <limit
      lower="-3.0543261"
      upper="3.0543261"
      effort="150"
      velocity="3.15" />
    <calibration
      rising="0"
      falling="0" />
    <dynamics
      damping="0"
      friction="0" />
    <safety_controller
      soft_upper_limit="3.0543261"
      soft_lower_limit="-3.0543261"
      k_position="100.0"
      k_velocity="40.0" />
  </joint>
  <link
    name="upperarm_Link">
    <inertial>
      <origin
        xyz="-2.2928E-05 0.33278 0.084237"
        rpy="0 0 0" />
      <mass
        value="14.46" />
      <inertia
        ixx="2.9074"
        ixy="-0.00023104"
        ixz="-2.5049E-05"
        iyy="0.12653"
        iyz="-0.1479"
        izz="2.8157" />
    </inertial>
    <visual>
      <origin
        xyz="0 0 0"
        rpy="0 0 0" />
      <geometry>
        <mesh
          filename="package://frcobot_description/meshes/fr5/visual/upperarm.dae" />
      </geometry>
      <material
        name="">
        <color
          rgba="0.89804 0.91765 0.92941 1" />
      </material>
    </visual>
    <collision>
      <origin
        xyz="0 0 0"
        rpy="0 0 0" />
      <geometry>
        <mesh
          filename="package://frcobot_description/meshes/fr5/collision/upperarm_Link.STL" />
      </geometry>
    </collision>
  </link>
  <joint
    name="j2"
    type="revolute">
    <origin
      xyz="0 0 0.155"
      rpy="1.570796 -1.570796 0" />
    <parent
      link="shoulder_Link" />
    <child
      link="upperarm_Link" />
    <axis
      xyz="0 0 1" />
    <limit
      lower="-4.6251225"
      upper="1.4835298"
      effort="150"
      velocity="3.15" />
    <calibration
      rising="0"
      falling="0" />
    <dynamics
      damping="0"
      friction="0" />
    <safety_controller
      soft_upper_limit="1.4835298"
      soft_lower_limit="-4.6251225"
      k_position="100"
      k_velocity="40" />
  </joint>
  <link
    name="forearm_Link">
    <inertial>
      <origin
        xyz="0.092224 -2.2928E-05 0.084237"
        rpy="0 0 0" />
      <mass
        value="7.67" />
      <inertia
        ixx="0.12653"
        ixy="0.00023104"
        ixz="0.1479"
        iyy="2.9074"
        iyz="-2.5049E-05"
        izz="2.8157" />
    </inertial>
    <visual>
      <origin
        xyz="0 0 0"
        rpy="0 0 0" />
      <geometry>
        <mesh
          filename="package://frcobot_description/meshes/fr5/visual/forearm.dae" />
      </geometry>
      <material
        name="">
        <color
          rgba="0.89804 0.91765 0.92941 1" />
      </material>
    </visual>
    <collision>
      <origin
        xyz="0 0 0"
        rpy="0 0 0" />
      <geometry>
        <mesh
          filename="package://frcobot_description/meshes/fr5/collision/forearm_Link.STL" />
      </geometry>
    </collision>
  </link>
  <joint
    name="j3"
    type="revolute">
    <origin
      xyz="0 0.425 0"
      rpy="0 0 -1.570796" />
    <parent
      link="upperarm_Link" />
    <child
      link="forearm_Link" />
    <axis
      xyz="0 0 1" />
    <limit
      lower="-2.8274333"
      upper="2.8274333"
      effort="150"
      velocity="3.15" />
    <calibration
      rising="0"
      falling="0" />
    <dynamics
      damping="0"
      friction="0" />
    <safety_controller
      soft_upper_limit="2.8274333"
      soft_lower_limit="-2.8274333"
      k_position="100"
      k_velocity="40" />
  </joint>
  <link
    name="wrist1_Link">
    <inertial>
      <origin
        xyz="0.48722 -2.2928E-05 0.084237"
        rpy="0 0 0" />
      <mass
        value="1.63" />
      <inertia
        ixx="0.12653"
        ixy="0.00023104"
        ixz="0.1479"
        iyy="2.9074"
        iyz="-2.5049E-05"
        izz="2.8157" />
    </inertial>
    <visual>
      <origin
        xyz="0 0 0"
        rpy="0 0 0" />
      <geometry>
        <mesh
          filename="package://frcobot_description/meshes/fr5/visual/wrist1.dae" />
      </geometry>
      <material
        name="">
        <color
          rgba="0.89804 0.91765 0.92941 1" />
      </material>
    </visual>
    <collision>
      <origin
        xyz="0 0 0"
        rpy="0 0 0" />
      <geometry>
        <mesh
          filename="package://frcobot_description/meshes/fr5/collision/wrist1_Link.STL" />
      </geometry>
    </collision>
  </link>
  <joint
    name="j4"
    type="revolute">
    <origin
      xyz="-0.395 0 0"
      rpy="0 0 1.570796" />
    <parent
      link="forearm_Link" />
    <child
      link="wrist1_Link" />
    <axis
      xyz="0 0 1" />
    <limit
      lower="-4.6251225"
      upper="1.4835298"
      effort="28"
      velocity="3.2" />
    <calibration
      rising="0"
      falling="0" />
    <dynamics
      damping="0"
      friction="0" />
    <safety_controller
      soft_upper_limit="1.4835298"
      soft_lower_limit="-4.6251225"
      k_position="100"
      k_velocity="40" />
  </joint>
  <link
    name="wrist2_Link">
    <inertial>
      <origin
        xyz="-2.396E-06 0.0045906 0.099342"
        rpy="0 0 0" />
      <mass
        value="1.58" />
      <inertia
        ixx="0.0022393"
        ixy="-1.0022E-07"
        ixz="-3.2115E-08"
        iyy="0.0013914"
        iyz="-2.2223E-05"
        izz="0.0021864" />
    </inertial>
    <visual>
      <origin
        xyz="0 0 0"
        rpy="0 0 0" />
      <geometry>
        <mesh
          filename="package://frcobot_description/meshes/fr5/visual/wrist2.dae" />
      </geometry>
      <material
        name="">
        <color
          rgba="0.89804 0.91765 0.92941 1" />
      </material>
    </visual>
    <collision>
      <origin
        xyz="0 0 0"
        rpy="0 0 0" />
      <geometry>
        <mesh
          filename="package://frcobot_description/meshes/fr5/collision/wrist2_Link.STL" />
      </geometry>
    </collision>
  </link>
  <joint
    name="j5"
    type="revolute">
    <origin
      xyz="0 0 0.13"
      rpy="1.570796 0 -1.570796" />
    <parent
      link="wrist1_Link" />
    <child
      link="wrist2_Link" />
    <axis
      xyz="0 0 1" />
    <limit
      lower="-3.0543261"
      upper="3.0543261"
      effort="28"
      velocity="3.2" />
    <calibration
      rising="0"
      falling="0" />
    <dynamics
      damping="0"
      friction="0" />
    <safety_controller
      soft_upper_limit="3.0543261"
      soft_lower_limit="-3.0543261"
      k_position="100"
      k_velocity="40" />
  </joint>
  <link
    name="wrist3_Link">
    <inertial>
      <origin
        xyz="5.8427E-06 7.5807E-05 0.079126"
        rpy="0 0 0" />
      <mass
        value="0.53" />
      <inertia
        ixx="0.00027801"
        ixy="-3.5346E-07"
        ixz="-1.7431E-07"
        iyy="0.00027736"
        iyz="-7.5888E-08"
        izz="0.00041582" />
    </inertial>
    <visual>
      <origin
        xyz="0 0 0"
        rpy="0 0 0" />
      <geometry>
        <mesh
          filename="package://frcobot_description/meshes/fr5/visual/wrist3.dae" />
      </geometry>
      <material
        name="">
        <color
          rgba="0.89804 0.91765 0.92941 1" />
      </material>
    </visual>
    <collision>
      <origin
        xyz="0 0 0"
        rpy="0 0 0" />
      <geometry>
        <mesh
          filename="package://frcobot_description/meshes/fr5/collision/wrist3_Link.STL" />
      </geometry>
    </collision>
  </link>
  <joint
    name="j6"
    type="revolute">
    <origin
      xyz="0 0 0.102"
      rpy="-1.570796 0 0" />
    <parent
      link="wrist2_Link" />
    <child
      link="wrist3_Link" />
    <axis
      xyz="0 0 1" />
    <limit
      lower="-3.0543261"
      upper="3.0543261"
      effort="28"
      velocity="3.2" />
    <calibration
      rising="0"
      falling="0" />
    <dynamics
      damping="0"
      friction="0" />
    <safety_controller
      soft_upper_limit="3.0543261"
      soft_lower_limit="-3.0543261"
      k_position="100"
      k_velocity="40" />
  </joint>
    <!-- 工具坐标系 (即末端执行器的坐标系) -->
  <link name="tool_Link">
    <!-- 可选的属性定义，例如碰撞体，形状，质量等 -->
  </link>

  <!-- 定义 wrist3_Link 和工具坐标系之间的变换关系 -->
  <joint name="wrist3_to_tool" type="fixed">
    <parent link="wrist3_Link"/>
    <child link="tool_Link"/>
    <!-- 工具坐标系相对于 wrist3_Link 的平移和旋转 -->
    <origin xyz="0 0 0.1" rpy="0 0 0"/>
  </joint>

<!-- 定义盘子的 link，改为长方体 -->
<link name="base_plate">
  <!-- 视觉信息 -->
  <visual>
    <geometry>
      <!-- 使用长方体，尺寸为 50 cm x 60 cm x 40 cm -->
      <box size="0.5 0.6 0.1"/>  <!-- 注意单位是米（meters），50 cm = 0.5 m，60 cm = 0.6 m，40 cm = 0.4 m -->
    </geometry>
    <material name="">
        <color
          rgba="0.89804 0.91765 0.92941 1" />
    </material>
  </visual>

  <!-- 碰撞信息 -->
  <collision>
    <geometry>
      <!-- 碰撞模型也用长方体 -->
      <box size="0.5 0.6 0.1"/>  <!-- 与视觉模型一致 -->
    </geometry>
  </collision>
</link>

<!-- 定义盘子与机械臂根部（base_link）之间的固定关节 -->
<joint name="base_to_plate" type="fixed">
  <parent link="base_link"/>  <!-- 假设 base_link 是机械臂的根部 link -->
  <child link="base_plate"/>
  <origin rpy="0 0 0" xyz="0 0 -0.12"/>  <!-- 盘子与 base_link 重合 -->
</joint>

</robot>
